Workbook

Sheet Read Me
A1: Risk Assessment Workbook: Anita & Daughters (Fictional)
A2: All people, companies, systems, and data in this workbook are fictional and were invented for a learning exercise.
A4: Tabs
A5: Tab | B5: What it holds | C5: Phase | D5: Status
A6: Assets | B6: Inventory of 18 assets with owner, data held, classification, and criticality | C6: 2 | D6: Complete
A7: Assumptions | B7: The invented starting conditions the risk register is based on | C7: 2 and 3 | D7: Complete
A8: Scoring Guide | B8: Likelihood and impact scales, rating bands, treatment options, and definitions | C8: 3 | D8: Complete
A9: Risk Register | B9: 15 risks, each tied to an asset, scored and rated by formula | C9: 3 | D9: Complete
A10: Summary | B10: Counts by rating and treatment, key numbers, and a likelihood-by-impact heat map | C10: 3 | D10: Complete
A11: Control Map | B11: 24 NIST CSF 2.0 controls with status, reason, and related risks | C11: 4 | D11: Complete
A12: Remediation Plan | B12: Prioritized fixes with owners and target dates | C12: 6 | D12: To fill in
A13: Evidence Tracker | B13: Proof an auditor would ask for, per control | C13: 7 | D13: To fill in
A15: How to read it
A16: Blue text = a number you can change (scores, thresholds). Black text = a formula or fixed text. Do not type over formulas.
A17: Light yellow rows with grey italic text = EXAMPLE rows. Replace them with your own entries and delete the example.
A18: Score = Likelihood x Impact (maximum 25). The rating (Low, Medium, High, Critical) comes from the minimum scores on the Scoring Guide tab.
A19: Asset IDs link the Assets and Risk Register tabs. The Risk Register looks up the asset name from its ID, and Assets counts its linked risks.
A20: The dollar ranges, time frames, and starting conditions are assumptions invented for this fictional firm. They are documented on the Scoring Guide and Assumptions tabs.

Sheet Assets
A1: Asset ID | B1: Asset | C1: Type | D1: What it is or does | E1: Owner | F1: Data it holds | G1: Classification | H1: Criticality (1-5) | I1: Location | J1: Linked risks
A2: A-01 | B2: Practice management and billing platform | C2: Application (cloud) | D2: Main system for patient accounts, charges, and claim creation | E2: Camille Williams, Billing Manager | F2: PHI | G2: Restricted | H2: 5 | I2: Vendor cloud | J2: =COUNTIF('Risk Register'!$B$2:$B$16,A2) -> 1
A3: A-02 | B3: Clearinghouse portal | C3: Application (third party) | D3: Submits claims to insurers and receives payments and denials | E3: Renee Washington, Claims and Denials Manager | F3: PHI | G3: Restricted | H3: 5 | I3: Vendor cloud | J3: =COUNTIF('Risk Register'!$B$2:$B$16,A3) -> 1
A4: A-03 | B4: Microsoft 365 tenant | C4: Cloud service | D4: Email, Teams chat, and OneDrive shared files | E4: Thanawat Charoen, IT Manager | F4: PHI in email and files; client contracts | G4: Restricted | H4: 5 | I4: Microsoft cloud | J4: =COUNTIF('Risk Register'!$B$2:$B$16,A4) -> 1
A5: A-04 | B5: Office file server | C5: Server | D5: Shared drives and scanned documents | E5: Thanawat Charoen, IT Manager | F5: PHI; client contracts; scanned documents | G5: Restricted | H5: 4 | I5: Newark office server room | J5: =COUNTIF('Risk Register'!$B$2:$B$16,A5) -> 1
A6: A-05 | B6: Staff laptops and desktops (about 50) | C6: Endpoint | D6: Daily work devices for every employee | E6: Thanawat Charoen, IT Manager | F6: Whatever each employee handles, including PHI | G6: Restricted | H6: 4 | I6: Office and staff homes | J6: =COUNTIF('Risk Register'!$B$2:$B$16,A6) -> 1
A7: A-06 | B7: VPN | C7: Network service | D7: Lets remote and hybrid staff reach office systems | E7: Thanawat Charoen, IT Manager | F7: Traffic to internal systems | G7: Confidential | H7: 4 | I7: Office firewall | J7: =COUNTIF('Risk Register'!$B$2:$B$16,A7) -> 1
A8: A-07 | B8: Cloud backup service | C8: Cloud service | D8: Nightly copies of the file server and key data | E8: Thanawat Charoen, IT Manager | F8: Copies of all data types | G8: Restricted | H8: 5 | I8: Vendor cloud | J8: =COUNTIF('Risk Register'!$B$2:$B$16,A8) -> 1
A9: A-08 | B9: Phone and call recording system | C9: Application | D9: Records client and patient calls | E9: Valerie Rivers, Customer Service Manager | F9: PHI spoken on calls; recordings | G9: Restricted | H9: 3 | I9: Vendor cloud | J9: =COUNTIF('Risk Register'!$B$2:$B$16,A9) -> 0
A10: A-09 | B10: Accounting and payroll software | C10: Application | D10: Company finances and payroll runs | E10: Bernard Hughes, Finance Manager | F10: Financial records; employee pay and bank details | G10: Restricted | H10: 4 | I10: Vendor cloud | J10: =COUNTIF('Risk Register'!$B$2:$B$16,A10) -> 1
A11: A-10 | B11: Website with patient payment page | C11: Web application | D11: Public site where patients pay balances by card | E11: Danielle Williams-Carter, COO | F11: Card data entered on a processor-hosted form | G11: Restricted | H11: 4 | I11: Web host and payment processor | J11: =COUNTIF('Risk Register'!$B$2:$B$16,A11) -> 0
A12: A-11 | B12: Office network (firewall, switches, Wi-Fi) | C12: Network | D12: Connects office devices and the internet | E12: Thanawat Charoen, IT Manager | F12: None stored | G12: Internal | H12: 4 | I12: Newark office | J12: =COUNTIF('Risk Register'!$B$2:$B$16,A12) -> 0
A13: A-12 | B13: Client contracts and pricing | C13: Data | D13: Agreements with each client practice | E13: Lorraine Bell, Client Relations Manager | F13: Contract terms and pricing | G13: Confidential | H13: 3 | I13: File server and OneDrive | J13: =COUNTIF('Risk Register'!$B$2:$B$16,A13) -> 1
... A19: A-18 | B19: Staff user accounts | C19: Identity | D19: The 50 employee logins to company systems | E19: Thanawat Charoen, IT Manager | F19: None stored; give access to PHI and other data | G19: Restricted | H19: 4 | I19: Microsoft 365 and vendor systems | J19: =COUNTIF('Risk Register'!$B$2:$B$16,A19) -> 3

Sheet Assumptions
A1: Starting Conditions (Invented)
A2: These conditions were invented for this fictional firm so the risk register has realistic weaknesses to work from. Use the same facts when you map controls in Phase 4. If you change one, update the related risks.
A4: ID | B4: Condition | C4: Assets affected | D4: Risks that use it
A5: S-01 | B5: MFA is required on the two IT administrator accounts only. Staff Microsoft 365 sign-ins use a password only. | C5: A-17, A-18 | D5: R-01
A6: S-02 | B6: The VPN requires a password only. The office firewall runs on default settings. | C6: A-06, A-11 | D6: R-05
A7: S-03 | B7: Laptops run built-in antivirus with no central management or monitoring. Staff install updates when prompted. | C7: A-05 | D7: R-02
A8: S-04 | B8: About 12 of 50 devices have full-disk encryption (those bought since 2024). | C8: A-05 | D8: R-04
A9: S-05 | B9: Cloud backups run nightly. Restores have never been tested. The backup console uses one shared password. | C9: A-07 | D9: R-03
A10: S-06 | B10: There is no written incident response plan. Staff tell the COO informally. | C10: A-01 | D10: R-10
A11: S-07 | B11: Security training is given once at hire, in English only. There has been no refresher since 2023. | C11: A-18 | D11: R-01, R-14
A12: S-08 | B12: The Claims team shares one clearinghouse portal login. | C12: A-02 | D12: R-06
A13: S-09 | B13: The file server is patched irregularly. The last full patching was about 5 months ago. | C13: A-04 | D13: R-02
A14: S-10 | B14: The outside IT help desk has one permanent remote-access account on all laptops. The contract has no security terms. | C14: A-15 | D14: R-08
A15: S-11 | B15: Leavers are removed when a manager emails IT. There is no checklist and no access review. | C15: A-18 | D15: R-07
... A22: S-18 | B22: There is no routine vulnerability scanning of laptops, the file server, or the network. | C22: A-04, A-05, A-11 | D22: R-02

Sheet Scoring Guide
A1: Scoring Guide
A3: Likelihood scale (how often could this happen?)
A4: Score | B4: Label | C4: Meaning | D4: Expected response
A5: 1 | B5: Rare | C5: Less than once in 10 years
A6: 2 | B6: Unlikely | C6: About once every 5 to 10 years
A7: 3 | B7: Possible | C7: About once every 1 to 5 years
A8: 4 | B8: Likely | C8: About once a year
A9: 5 | B9: Almost certain | C9: Several times a year, or already happening
A11: Impact scale (how bad would it be?)
A12: Score | B12: Label | C12: Meaning
A13: 1 | B13: Minimal | C13: Minor inconvenience. No data exposed. Under $1,000.
A14: 2 | B14: Minor | C14: Small delay of a few hours. Under $5,000.
A15: 3 | B15: Moderate | C15: A day or more of lost work, or limited data exposed. $5,000 to $50,000.
A16: 4 | B16: Major | C16: Many patients' PHI exposed or billing down for days. Breach notification required. $50,000 to $250,000.
A17: 5 | B17: Severe | C17: Prolonged shutdown, a large breach, or loss of clients. Over $250,000.
A19: Rating bands (Score = Likelihood x Impact, maximum 25)
A20: Rating | B20: Minimum score | C20: Meaning | D20: Expected response
A21: Low | B21: 1 | C21: Acceptable with monitoring | D21: Review at the annual assessment
A22: Medium | B22: 5 | C22: Needs a planned fix | D22: Fix within 6 months
A23: High | B23: 10 | C23: Needs prompt attention | D23: Fix within 90 days
A24: Critical | B24: 17 | C24: Unacceptable | D24: Fix within 30 days
A25: The minimum scores in blue are the cut-offs the Risk Register uses. Change them here and every rating updates.
A27: Treatment options
A28: Option | B28: Meaning
A29: Mitigate | B29: Reduce the risk with a control or a change.
A30: Accept | B30: Knowingly live with the risk. Record why, and revisit at the next review.
A31: Transfer | B31: Shift part of the cost to someone else, for example through insurance or a contract.
A32: Avoid | B32: Stop the activity that creates the risk.
A34: Asset criticality (how much does the business depend on it?)
A35: Score | B35: Label | C35: Meaning
A36: 1 | B36: Very low | C36: Barely noticed if lost
A37: 2 | B37: Low | C37: Work continues with a workaround
A38: 3 | B38: Medium | C38: Some teams are slowed for a day or more
A39: 4 | B39: High | C39: Many staff cannot work, or sensitive data is at stake
A40: 5 | B40: Essential | C40: Billing stops, or data is lost permanently
A42: Data classification
A43: Level | B43: Meaning
A44: Restricted | B44: PHI, card data, payroll and employee records. A breach triggers legal or contractual notice.
A45: Confidential | B45: Business information that should stay inside the company, such as contracts and pricing.
A46: Internal | B46: Everything else used for running the office.
...

Sheet Risk Register
A1: Risk ID | B1: Asset ID | C1: Asset | D1: Risk statement | E1: Threat | F1: Vulnerability | G1: Likelihood (1-5) | H1: Impact (1-5) | I1: Score | J1: Rating | K1: Existing controls | L1: Treatment | M1: Risk owner | N1: Notes
A2: R-01 | B2: A-18 | C2: =IFERROR(INDEX(Assets!$B$2:$B$19,MATCH(B2,Assets!$A$2:$A$19,0)),"Check asset ID") -> Staff user accounts | D2: A phishing email could capture a staff password, letting an attacker read PHI in that person's mailbox and files. | E2: Phishing | F2: Staff sign in with a password only (no MFA), and there has been no security refresher training since 2023 | G2: 5 | H2: 4 | I2: =G2*H2 -> 20 | J2: =IF(I2>='Scoring Guide'!$B$24,"Critical",IF(I2>='Scoring Guide'!$B$23,"High",IF(I2>='Scoring Guide'!$B$22,"Medium","Low"))) -> Critical | K2: Microsoft 365 spam filtering | L2: Mitigate | M2: Thanawat Charoen, IT Manager | N2: Most likely way an attacker gets in at a billing firm.
A3: R-02 | B3: A-04 | C3: =IFERROR(INDEX(Assets!$B$2:$B$19,MATCH(B3,Assets!$A$2:$A$19,0)),"Check asset ID") -> Office file server | D3: Ransomware could encrypt the file server and stop billing work for days. | E3: Ransomware | F3: The server is patched irregularly (last full patching about 5 months ago) and laptops have no central management or monitoring | G3: 4 | H3: 5 | I3: =G3*H3 -> 20 | J3: =IF(I3>='Scoring Guide'!$B$24,"Critical",IF(I3>='Scoring Guide'!$B$23,"High",IF(I3>='Scoring Guide'!$B$22,"Medium","Low"))) -> Critical | K3: Built-in antivirus on laptops; nightly cloud backup | L3: Mitigate | M3: Thanawat Charoen, IT Manager | N3: Cyber insurance could also transfer part of the cost.
A4: R-03 | B4: A-07 | C4: =IFERROR(INDEX(Assets!$B$2:$B$19,MATCH(B4,Assets!$A$2:$A$19,0)),"Check asset ID") -> Cloud backup service | D4: A failed or corrupted backup could leave the firm unable to recover after an incident. | E4: Ransomware, hardware failure, or accidental deletion | F4: Restores have never been tested, and the backup console uses one shared password | G4: 3 | H4: 5 | I4: =G4*H4 -> 15 | J4: =IF(I4>='Scoring Guide'!$B$24,"Critical",IF(I4>='Scoring Guide'!$B$23,"High",IF(I4>='Scoring Guide'!$B$22,"Medium","Low"))) -> High | K4: Nightly backup job runs | L4: Mitigate | M4: Thanawat Charoen, IT Manager
A5: R-04 | B5: A-05 | C5: =IFERROR(INDEX(Assets!$B$2:$B$19,MATCH(B5,Assets!$A$2:$A$19,0)),"Check asset ID") -> Staff laptops and desktops (about 50) | D5: A lost or stolen laptop could expose PHI. | E5: Theft or loss, especially for the 24 hybrid and remote staff | F5: Only about 12 of 50 devices have full-disk encryption | G5: 3 | H5: 4 | I5: =G5*H5 -> 12 | J5: =IF(I5>='Scoring Guide'!$B$24,"Critical",IF(I5>='Scoring Guide'!$B$23,"High",IF(I5>='Scoring Guide'!$B$22,"Medium","Low"))) -> High | K5: Device login passwords | L5: Mitigate | M5: Thanawat Charoen, IT Manager
A6: R-05 | B6: A-06 | C6: =IFERROR(INDEX(Assets!$B$2:$B$19,MATCH(B6,Assets!$A$2:$A$19,0)),"Check asset ID") -> VPN | D6: Attackers could guess or reuse passwords to log in to the VPN and reach office systems. | E6: Password guessing and credential stuffing | F6: The VPN requires a password only | G6: 4 | H6: 4 | I6: =G6*H6 -> 16 | J6: =IF(I6>='Scoring Guide'!$B$24,"Critical",IF(I6>='Scoring Guide'!$B$23,"High",IF(I6>='Scoring Guide'!$B$22,"Medium","Low"))) -> High | K6: Default firewall settings | L6: Mitigate | M6: Thanawat Charoen, IT Manager
A7: R-06 | B7: A-02 | C7: =IFERROR(INDEX(Assets!$B$2:$B$19,MATCH(B7,Assets!$A$2:$A$19,0)),"Check asset ID") -> Clearinghouse portal | D7: A shared clearinghouse login means the firm cannot tell who viewed or changed a claim, and one leaked password exposes the whole portal. | E7: Insider misuse or a compromised credential | F7: The Claims team shares one login | G7: 3 | H7: 4 | I7: =G7*H7 -> 12 | J7: =IF(I7>='Scoring Guide'!$B$24,"Critical",IF(I7>='Scoring Guide'!$B$23,"High",IF(I7>='Scoring Guide'!$B$22,"Medium","Low"))) -> High | K7: The portal's own session timeout | L7: Mitigate | M7: Renee Washington, Claims and Denials Manager
A8: R-07 | B8: A-18 | C8: =IFERROR(INDEX(Assets!$B$2:$B$19,MATCH(B8,Assets!$A$2:$A$19,0)),"Check asset ID") -> Staff user accounts | D8: A former employee's account could stay active after they leave and still reach PHI. | E8: Misuse by a former employee | F8: No offboarding checklist and no routine access review; removal depends on a manager's email | G8: 3 | H8: 4 | I8: =G8*H8 -> 12 | J8: =IF(I8>='Scoring Guide'!$B$24,"Critical",IF(I8>='Scoring Guide'!$B$23,"High",IF(I8>='Scoring Guide'!$B$22,"Medium","Low"))) -> High | K8: Manager emails IT when someone leaves | L8: Mitigate | M8: Yolanda Greene, HR Manager | N8: The IAM lab's leaver process is the model for the fix.
A9: R-08 | B9: A-15 | C9: =IFERROR(INDEX(Assets!$B$2:$B$19,MATCH(B9,Assets!$A$2:$A$19,0)),"Check asset ID") -> Outside IT help desk | D9: If the outside help desk's remote-access account were compromised, an attacker could reach every laptop. | E9: Supply chain compromise | F9: One permanent vendor account has remote access, and the contract has no security terms | G9: 2 | H9: 5 | I9: =G9*H9 -> 10 | J9: =IF(I9>='Scoring Guide'!$B$24,"Critical",IF(I9>='Scoring Guide'!$B$23,"High",IF(I9>='Scoring Guide'!$B$22,"Medium","Low"))) -> High | K9: Contract with a confidentiality clause | L9: Mitigate | M9: Pimchanok Wongsawat, Compliance and Privacy Officer
A10: R-09 | B10: A-03 | C10: =IFERROR(INDEX(Assets!$B$2:$B$19,MATCH(B10,Assets!$A$2:$A$19,0)),"Check asset ID") -> Microsoft 365 tenant | D10: Suspicious Microsoft 365 sign-ins could go unnoticed for weeks. | E10: Account takeover | F10: No one reviews sign-in logs or alerts | G10: 3 | H10: 3 | I10: =G10*H10 -> 9 | J10: =IF(I10>='Scoring Guide'!$B$24,"Critical",IF(I10>='Scoring Guide'!$B$23,"High",IF(I10>='Scoring Guide'!$B$22,"Medium","Low"))) -> Medium | K10: Default Microsoft 365 alerts | L10: Mitigate | M10: Thanawat Charoen, IT Manager
A11: R-10 | B11: A-01 | C11: =IFERROR(INDEX(Assets!$B$2:$B$19,MATCH(B11,Assets!$A$2:$A$19,0)),"Check asset ID") -> Practice management and billing platform | D11: Without an incident response plan, staff may not know who to call, and the firm may miss breach notification deadlines. | E11: Any security incident | F11: No written incident response plan or contact list | G11: 3 | H11: 4 | I11: =G11*H11 -> 12 | J11: =IF(I11>='Scoring Guide'!$B$24,"Critical",IF(I11>='Scoring Guide'!$B$23,"High",IF(I11>='Scoring Guide'!$B$22,"Medium","Low"))) -> High | K11: Staff tell the COO informally | L11: Mitigate | M11: Pimchanok Wongsawat, Compliance and Privacy Officer
A12: R-11 | B12: A-16 | C12: =IFERROR(INDEX(Assets!$B$2:$B$19,MATCH(B12,Assets!$A$2:$A$19,0)),"Check asset ID") -> Payment processor | D12: A compromised payment page could skim patient card numbers. | E12: Web skimming | F12: The processor's security attestation is not on file, and the payment page is not reviewed | G12: 2 | H12: 4 | I12: =G12*H12 -> 8 | J12: =IF(I12>='Scoring Guide'!$B$24,"Critical",IF(I12>='Scoring Guide'!$B$23,"High",IF(I12>='Scoring Guide'!$B$22,"Medium","Low"))) -> Medium | K12: Card entry form is hosted by the processor | L12: Mitigate | M12: Danielle Williams-Carter, COO
A13: R-12 | B13: A-09 | C13: =IFERROR(INDEX(Assets!$B$2:$B$19,MATCH(B13,Assets!$A$2:$A$19,0)),"Check asset ID") -> Accounting and payroll software | D13: A scam email posing as an employee could change their direct-deposit details and divert a paycheck. | E13: Business email compromise | F13: Bank detail changes are accepted by email | G13: 3 | H13: 3 | I13: =G13*H13 -> 9 | J13: =IF(I13>='Scoring Guide'!$B$24,"Critical",IF(I13>='Scoring Guide'!$B$23,"High",IF(I13>='Scoring Guide'!$B$22,"Medium","Low"))) -> Medium | K13: Payroll asks the employee's manager to confirm by email | L13: Mitigate | M13: Bernard Hughes, Finance Manager
A14: R-13 | B14: A-14 | C14: =IFERROR(INDEX(Assets!$B$2:$B$19,MATCH(B14,Assets!$A$2:$A$19,0)),"Check asset ID") -> Printed claim documents and patient statements | D14: Printed claim documents could be read or taken from an unlocked cabinet or from the recycling. | E14: Theft or improper disposal | F14: Cabinets are unlocked, and the shredding bin is emptied monthly | G14: 2 | H14: 3 | I14: =G14*H14 -> 6 | J14: =IF(I14>='Scoring Guide'!$B$24,"Critical",IF(I14>='Scoring Guide'!$B$23,"High",IF(I14>='Scoring Guide'!$B$22,"Medium","Low"))) -> Medium | K14: Office door is locked after hours | L14: Mitigate | M14: Camille Williams, Billing Manager
A15: R-14 | B15: A-18 | C15: =IFERROR(INDEX(Assets!$B$2:$B$19,MATCH(B15,Assets!$A$2:$A$19,0)),"Check asset ID") -> Staff user accounts | D15: Some staff could miss or misread security instructions because training and policies exist only in English. | E15: Human error | F15: Training and policies are not offered in Thai | G15: 3 | H15: 2 | I15: =G15*H15 -> 6 | J15: =IF(I15>='Scoring Guide'!$B$24,"Critical",IF(I15>='Scoring Guide'!$B$23,"High",IF(I15>='Scoring Guide'!$B$22,"Medium","Low"))) -> Medium | K15: Training given once at hire | L15: Mitigate | M15: Pimchanok Wongsawat, Compliance and Privacy Officer | N15: Staff support clients in English and Thai.
A16: R-15 | B16: A-12 | C16: =IFERROR(INDEX(Assets!$B$2:$B$19,MATCH(B16,Assets!$A$2:$A$19,0)),"Check asset ID") -> Client contracts and pricing | D16: Client contracts could be read by staff who do not need them. | E16: Unauthorized internal access | F16: All staff can read the contracts folder on the file server | G16: 2 | H16: 2 | I16: =G16*H16 -> 4 | J16: =IF(I16>='Scoring Guide'!$B$24,"Critical",IF(I16>='Scoring Guide'!$B$23,"High",IF(I16>='Scoring Guide'!$B$22,"Medium","Low"))) -> Low | K16: The folder is not shared outside the company | L16: Accept | M16: Lorraine Bell, Client Relations Manager | N16: Accepted for now because contracts are less sensitive than PHI. Revisit at the annual review.

Sheet Summary
A1: Risk Summary
A3: Risks by rating | I3: Band minimums (from Scoring Guide)
A4: Rating | B4: Count | C4: Share | I4: Critical | J4: ='Scoring Guide'!$B$24 -> 17
A5: Critical | B5: =COUNTIF('Risk Register'!$J$2:$J$16,A5) -> 2 | C5: =IF($B$9=0,0,B5/$B$9) -> 0.13333333 | I5: High | J5: ='Scoring Guide'!$B$23 -> 10
A6: High | B6: =COUNTIF('Risk Register'!$J$2:$J$16,A6) -> 7 | C6: =IF($B$9=0,0,B6/$B$9) -> 0.46666667 | I6: Medium | J6: ='Scoring Guide'!$B$22 -> 5
A7: Medium | B7: =COUNTIF('Risk Register'!$J$2:$J$16,A7) -> 5 | C7: =IF($B$9=0,0,B7/$B$9) -> 0.33333333
A8: Low | B8: =COUNTIF('Risk Register'!$J$2:$J$16,A8) -> 1 | C8: =IF($B$9=0,0,B8/$B$9) -> 0.066666667
A9: Total | B9: =SUM(B5:B8) -> 15 | C9: =SUM(C5:C8) -> 1
A11: Key numbers
A12: Risks in the register | B12: =COUNTA('Risk Register'!$A$2:$A$16) -> 15
A13: Average risk score | B13: =AVERAGE('Risk Register'!$I$2:$I$16) -> 11.4
A14: Highest risk score | B14: =MAX('Risk Register'!$I$2:$I$16) -> 20
A15: Assets in the inventory | B15: =COUNTA(Assets!$A$2:$A$19) -> 18
A16: Restricted assets | B16: =COUNTIF(Assets!$G$2:$G$19,"Restricted") -> 15
A17: Assets with no linked risk yet | B17: =COUNTIF(Assets!$J$2:$J$19,0) -> 5
A19: Risks by treatment
A20: Treatment | B20: Count
A21: Mitigate | B21: =COUNTIF('Risk Register'!$L$2:$L$16,A21) -> 14
A22: Accept | B22: =COUNTIF('Risk Register'!$L$2:$L$16,A22) -> 1
A23: Transfer | B23: =COUNTIF('Risk Register'!$L$2:$L$16,A23) -> 0
A24: Avoid | B24: =COUNTIF('Risk Register'!$L$2:$L$16,A24) -> 0
A27: Heat map: number of risks by likelihood and impact
C28: Likelihood
A29: Impact | B29: Score | C29: 1 | D29: 2 | E29: 3 | F29: 4 | G29: 5
A30: Severe | B30: 5 | C30: =COUNTIFS('Risk Register'!$G$2:$G$16,C$29,'Risk Register'!$H$2:$H$16,$B30) -> 0 | D30: =COUNTIFS('Risk Register'!$G$2:$G$16,D$29,'Risk Register'!$H$2:$H$16,$B30) -> 1 | E30: =COUNTIFS('Risk Register'!$G$2:$G$16,E$29,'Risk Register'!$H$2:$H$16,$B30) -> 1 | F30: =COUNTIFS('Risk Register'!$G$2:$G$16,F$29,'Risk Register'!$H$2:$H$16,$B30) -> 1 | G30: =COUNTIFS('Risk Register'!$G$2:$G$16,G$29,'Risk Register'!$H$2:$H$16,$B30) -> 0
A31: Major | B31: 4 | C31: =COUNTIFS('Risk Register'!$G$2:$G$16,C$29,'Risk Register'!$H$2:$H$16,$B31) -> 0 | D31: =COUNTIFS('Risk Register'!$G$2:$G$16,D$29,'Risk Register'!$H$2:$H$16,$B31) -> 1 | E31: =COUNTIFS('Risk Register'!$G$2:$G$16,E$29,'Risk Register'!$H$2:$H$16,$B31) -> 4 | F31: =COUNTIFS('Risk Register'!$G$2:$G$16,F$29,'Risk Register'!$H$2:$H$16,$B31) -> 1 | G31: =COUNTIFS('Risk Register'!$G$2:$G$16,G$29,'Risk Register'!$H$2:$H$16,$B31) -> 1
A32: Moderate | B32: 3 | C32: =COUNTIFS('Risk Register'!$G$2:$G$16,C$29,'Risk Register'!$H$2:$H$16,$B32) -> 0 | D32: =COUNTIFS('Risk Register'!$G$2:$G$16,D$29,'Risk Register'!$H$2:$H$16,$B32) -> 1 | E32: =COUNTIFS('Risk Register'!$G$2:$G$16,E$29,'Risk Register'!$H$2:$H$16,$B32) -> 2 | F32: =COUNTIFS('Risk Register'!$G$2:$G$16,F$29,'Risk Register'!$H$2:$H$16,$B32) -> 0 | G32: =COUNTIFS('Risk Register'!$G$2:$G$16,G$29,'Risk Register'!$H$2:$H$16,$B32) -> 0
A33: Minor | B33: 2 | C33: =COUNTIFS('Risk Register'!$G$2:$G$16,C$29,'Risk Register'!$H$2:$H$16,$B33) -> 0 | D33: =COUNTIFS('Risk Register'!$G$2:$G$16,D$29,'Risk Register'!$H$2:$H$16,$B33) -> 1 | E33: =COUNTIFS('Risk Register'!$G$2:$G$16,E$29,'Risk Register'!$H$2:$H$16,$B33) -> 1 | F33: =COUNTIFS('Risk Register'!$G$2:$G$16,F$29,'Risk Register'!$H$2:$H$16,$B33) -> 0 | G33: =COUNTIFS('Risk Register'!$G$2:$G$16,G$29,'Risk Register'!$H$2:$H$16,$B33) -> 0
A34: Minimal | B34: 1 | C34: =COUNTIFS('Risk Register'!$G$2:$G$16,C$29,'Risk Register'!$H$2:$H$16,$B34) -> 0 | D34: =COUNTIFS('Risk Register'!$G$2:$G$16,D$29,'Risk Register'!$H$2:$H$16,$B34) -> 0 | E34: =COUNTIFS('Risk Register'!$G$2:$G$16,E$29,'Risk Register'!$H$2:$H$16,$B34) -> 0 | F34: =COUNTIFS('Risk Register'!$G$2:$G$16,F$29,'Risk Register'!$H$2:$H$16,$B34) -> 0 | G34: =COUNTIFS('Risk Register'!$G$2:$G$16,G$29,'Risk Register'!$H$2:$H$16,$B34) -> 0
A36: Cell colors follow the rating bands on the Scoring Guide tab. A dash means no risks in that cell.

Sheet Control Map
A1: Control Map (NIST CSF 2.0)
A2: Status comes from the Assumptions tab (S-numbers). Subcategory IDs are from NIST CSF 2.0; the plain-language column is paraphrased. Partial and Missing rows are the gaps carried into Phase 6. | I2: Control status by function
A3: Function | B3: Category | C3: Subcategory ID | D3: What it means in plain words | E3: Status | F3: Evidence or reason | G3: Related risk IDs | I3: Function | J3: Implemented | K3: Partial | L3: Missing | M3: Total
A4: Govern | B4: GV.RR | C4: GV.RR-02 | D4: Someone is named responsible for cybersecurity risk, and everyone knows who | E4: Partial | F4: The COO is the informal contact for incidents, but no security roles are written down (S-06) | G4: R-10 | I4: Govern | J4: =COUNTIFS($A$4:$A$60,$I4,$E$4:$E$60,J$3) -> 0 | K4: =COUNTIFS($A$4:$A$60,$I4,$E$4:$E$60,K$3) -> 1 | L4: =COUNTIFS($A$4:$A$60,$I4,$E$4:$E$60,L$3) -> 2 | M4: =SUM(J4:L4) -> 3
A5: Govern | B5: GV.PO | C5: GV.PO-01 | D5: The company has a written policy for managing cybersecurity risk | E5: Missing | F5: No written security policies exist (S-17). Phase 5 drafts access control, incident response, and acceptable use policies | G5: R-07, R-10 | I5: Identify | J5: =COUNTIFS($A$4:$A$60,$I5,$E$4:$E$60,J$3) -> 3 | K5: =COUNTIFS($A$4:$A$60,$I5,$E$4:$E$60,K$3) -> 1 | L5: =COUNTIFS($A$4:$A$60,$I5,$E$4:$E$60,L$3) -> 0 | M5: =SUM(J5:L5) -> 4
A6: Govern | B6: GV.SC | C6: GV.SC-05 | D6: Vendors must meet security requirements, and those requirements are written into contracts | E6: Missing | F6: The IT help desk contract has no security terms, and the payment processor's security attestation is not on file (S-10, S-15) | G6: R-08, R-11 | I6: Protect | J6: =COUNTIFS($A$4:$A$60,$I6,$E$4:$E$60,J$3) -> 0 | K6: =COUNTIFS($A$4:$A$60,$I6,$E$4:$E$60,K$3) -> 8 | L6: =COUNTIFS($A$4:$A$60,$I6,$E$4:$E$60,L$3) -> 3 | M6: =SUM(J6:L6) -> 11
A7: Identify | B7: ID.AM | C7: ID.AM-02 | D7: The company keeps a list of its software, services, and systems | E7: Implemented | F7: The Assets tab lists 10 systems and 8 supporting assets. It was created in this assessment and needs an owner to keep it current | G7: All | I7: Detect | J7: =COUNTIFS($A$4:$A$60,$I7,$E$4:$E$60,J$3) -> 0 | K7: =COUNTIFS($A$4:$A$60,$I7,$E$4:$E$60,K$3) -> 0 | L7: =COUNTIFS($A$4:$A$60,$I7,$E$4:$E$60,L$3) -> 2 | M7: =SUM(J7:L7) -> 2
A8: Identify | B8: ID.AM | C8: ID.AM-05 | D8: Assets are ranked by how sensitive and how important they are | E8: Implemented | F8: Every asset has a classification and a 1 to 5 criticality score on the Assets tab | G8: All | I8: Respond | J8: =COUNTIFS($A$4:$A$60,$I8,$E$4:$E$60,J$3) -> 0 | K8: =COUNTIFS($A$4:$A$60,$I8,$E$4:$E$60,K$3) -> 0 | L8: =COUNTIFS($A$4:$A$60,$I8,$E$4:$E$60,L$3) -> 2 | M8: =SUM(J8:L8) -> 2
A9: Identify | B9: ID.RA | C9: ID.RA-01 | D9: Weaknesses in systems are found and written down | E9: Partial | F9: Known weaknesses are recorded in this assessment, but there is no routine vulnerability scanning (S-18) | G9: R-02, R-04 | I9: Recover | J9: =COUNTIFS($A$4:$A$60,$I9,$E$4:$E$60,J$3) -> 0 | K9: =COUNTIFS($A$4:$A$60,$I9,$E$4:$E$60,K$3) -> 0 | L9: =COUNTIFS($A$4:$A$60,$I9,$E$4:$E$60,L$3) -> 2 | M9: =SUM(J9:L9) -> 2
A10: Identify | B10: ID.RA | C10: ID.RA-05 | D10: Threats, weaknesses, likelihood, and impact are used to rank risks | E10: Implemented | F10: The Risk Register scores 15 risks by likelihood times impact | G10: All | I10: Total | J10: =SUM(J4:J9) -> 3 | K10: =SUM(K4:K9) -> 10 | L10: =SUM(L4:L9) -> 11 | M10: =SUM(M4:M9) -> 24
A11: Protect | B11: PR.AA | C11: PR.AA-01 | D11: Each person, service, and device has its own managed identity and credentials | E11: Partial | F11: Staff have individual Microsoft 365 accounts, but the Claims team shares one portal login and the backup console shares one password (S-05, S-08) | G11: R-03, R-06
A12: Protect | B12: PR.AA | C12: PR.AA-03 | D12: Users, services, and hardware prove who they are before getting access | E12: Partial | F12: MFA is on the 2 IT admin accounts only. Staff and VPN logins use a password only (S-01, S-02) | G12: R-01, R-05 | I12: Gaps to carry into Phase 6 (Partial + Missing) | M12: =K10+L10 -> 21
A13: Protect | B13: PR.AA | C13: PR.AA-05 | D13: Access is defined in a policy, limited to what each job needs, and reviewed | E13: Missing | F13: No access reviews; leavers are removed when a manager emails IT; all staff can read the contracts folder (S-11, S-16) | G13: R-07, R-15
A14: Protect | B14: PR.AA | C14: PR.AA-06 | D14: Physical access to offices, devices, and paper records is controlled | E14: Partial | F14: The office door is locked after hours, but printed claim documents sit in unlocked cabinets (S-14) | G14: R-13
A15: Protect | B15: PR.AT | C15: PR.AT-01 | D15: Staff get security awareness and training that fits their jobs | E15: Partial | F15: Training is given once at hire, in English only, with no refresher since 2023 (S-07) | G15: R-01, R-14
A16: Protect | B16: PR.AT | C16: PR.AT-02 | D16: People in specialized roles get training that fits their risks | E16: Missing | F16: Payroll and finance staff have not been trained to spot fake bank-detail change requests, which are accepted by email (S-13) | G16: R-12
A17: Protect | B17: PR.DS | C17: PR.DS-01 | D17: Stored data is protected, for example by encryption | E17: Partial | F17: About 12 of 50 devices have full-disk encryption (S-04) | G17: R-04
A18: Protect | B18: PR.DS | C18: PR.DS-11 | D18: Backups are created, protected, and tested | E18: Partial | F18: Nightly backups run, but restores are untested and the console uses a shared password (S-05) | G18: R-02, R-03
A19: Protect | B19: PR.PS | C19: PR.PS-01 | D19: Systems are set up in a standard, managed way | E19: Missing | F19: Laptops have no standard configuration or central management (S-03) | G19: R-02
A20: Protect | B20: PR.PS | C20: PR.PS-02 | D20: Software is kept up to date and old software is retired | E20: Partial | F20: The file server is patched irregularly, and staff install laptop updates when prompted (S-03, S-09) | G20: R-02
A21: Protect | B21: PR.IR | C21: PR.IR-01 | D21: Networks are protected from unauthorized access | E21: Partial | F21: The firewall runs on default settings, and the VPN accepts a password alone (S-02) | G21: R-05
A22: Detect | B22: DE.CM | C22: DE.CM-03 | D22: Staff activity and technology use are watched for signs of trouble | E22: Missing | F22: No one reviews Microsoft 365 sign-in logs or alerts (S-12) | G22: R-09
A23: Detect | B23: DE.AE | C23: DE.AE-02 | D23: Suspicious events are analyzed to understand what is happening | E23: Missing | F23: There is no process for analyzing alerts when they appear (S-12) | G23: R-09
A24: Respond | B24: RS.MA | C24: RS.MA-01 | D24: The incident response plan is carried out once an incident is declared | E24: Missing | F24: There is no written incident response plan (S-06) | G24: R-10
... A27: Recover | B27: RC.RP | C27: RC.RP-03 | D27: Backups are checked for integrity before they are used to restore | E27: Missing | F27: Restores have never been tested, and no integrity checks are done (S-05) | G27: R-03

Sheet Remediation Plan
A1: Remediation Plan: fill in during Phase 6
A2: One row per gap (a control marked Partial or Missing). Rank by the highest linked risk score. Delete the yellow example row when you add your own.
A3: Gap ID | B3: Action | C3: Linked risk IDs | D3: Linked control | E3: Priority | F3: Owner | G3: Effort | H3: Target date | I3: Status | J3: Success measure
A4: EXAMPLE: GAP-01 | B4: Turn on MFA for all staff Microsoft 365 accounts | C4: R-01 | D4: PR.AA-03 | E4: P1 | F4: Thanawat Charoen, IT Manager | G4: Medium | H4: 46371 | I4: Not started | J4: 100% of staff accounts show MFA registered in the sign-in report

Sheet Evidence Tracker
A1: Mock Audit Evidence Tracker: fill in during Phase 7
A2: For each control, list the proof an auditor would ask for. Delete the yellow example row when you add your own.
A3: Control (CSF ID) | B3: Control in plain words | C3: Evidence an auditor would ask for | D3: Where it lives | E3: Owner | F3: How often | G3: Status | H3: Notes
A4: EXAMPLE: PR.AA-05 | B4: Access is reviewed and kept to what each job needs | C4: Quarterly user access review, signed by each manager | D4: Shared drive: Compliance / Access Reviews | E4: Pimchanok Wongsawat, Compliance and Privacy Officer | F4: Quarterly | G4: Missing | H4: No review has been done yet
